Workbook

Sheet Lists
A1: Dependency Types | B1: Logic | C1: Impact | D1: Confidence | E1: Interpretation Type | F1: Status | G1: Scale Sensitivity | H1: Evidence Values
A2: Prerequisite | B2: Direct | C2: 0 | D2: High | E2: Standard-supported | F2: Draft | G2: Universal | H2: Yes
A3: Data | B3: AND | C3: 25 | D3: Medium | E3: Professional interpretation | F3: Reviewed | G3: Scaling-sensitive | H3: Partial
A4: Operational | B4: OR | C4: 50 | D4: Low | E4: Organisation-specific | F4: Validated | G4: Complex-environment | H4: No
A5: Evidence | C5: 75 | E5: Hypothesis | G5: Regulated/high-risk
A6: Governance | C6: 100
A7: Risk

Sheet Controls
A1: Control ID | B1: Control name | C1: Source | D1: Control category | E1: FAIR-CAM functions | F1: Scale sensitivity | G1: Plain-language description | H1: Status
A2: 4.3 | B2: Determining the scope of the ISMS | C2: Clause | D2: Governance / Foundation | E2: Decision Support: Define expectations; Asset data context | F2: Universal | G2: Defines the organisational, technical and information boundaries within which controls must operate. | H2: Draft
A3: 5.3 | B3: Organisational roles, responsibilities and authorities | C3: Clause | D3: Governance / Foundation | E3: Decision Support: Define expectations; Ensure capability | F3: Universal | G3: Assigns accountability, authority and responsibility for information security activities. | H3: Draft
A4: 6.1.2 | B4: Information security risk assessment | C4: Clause | D4: Decision Support | E4: Decision Support: Analysis | F4: Universal | G4: Provides the risk context used to prioritise assets, controls and treatment activities. | H4: Draft
A5: 7.5 | B5: Documented information | C5: Clause | D5: Governance / Evidence | E5: Decision Support: Data; Reporting | F5: Universal | G5: Controls the creation, approval, availability, integrity and maintenance of documented information. | H5: Draft
A6: 8.1 | B6: Operational planning and control | C6: Clause | D6: Execution / Governance | E6: Decision Support: Define expectations; Variance Prevention | F6: Universal | G6: Turns planned requirements into controlled operational activities and managed changes. | H6: Draft
A7: 9.1 | B7: Monitoring, measurement, analysis and evaluation | C7: Clause | D7: Oversight | E7: Decision Support: Control data; Analysis; Reporting; Variance Identification | F7: Universal | G7: Evaluates whether the ISMS and selected controls operate and achieve expected results. | H7: Draft
A8: 10.1 | B8: Continual improvement | C8: Clause | D8: Improvement | E8: Variance Correction: Treatment selection; Implementation | F8: Universal | G8: Uses findings and performance information to correct weaknesses and improve the ISMS. | H8: Draft
A9: A.5.2 | B9: Information security roles and responsibilities | C9: Annex A | D9: Governance / Foundation | E9: Decision Support: Define expectations; Ensure capability | F9: Universal | G9: Defines operational information security ownership and responsibility. | H9: Draft
A10: A.5.7 | B10: Threat intelligence | C10: Annex A | D10: Decision Support | E10: Decision Support: Threat data; Variance Identification | F10: Scaling-sensitive | G10: Provides information about relevant threats and changes in the threat environment. | H10: Draft
A11: A.5.9 | B11: Inventory of information and other associated assets | C11: Annex A | D11: Foundation / Decision Support | E11: Decision Support: Asset data | F11: Universal | G11: Provides a maintained view of assets, ownership and other information needed to protect them. | H11: Draft
A12: A.5.24 | B12: Information security incident management planning and preparation | C12: Annex A | D12: Response / Governance | E12: Decision Support: Define expectations; Ensure capability; Loss Event Response | F12: Scaling-sensitive | G12: Establishes roles, procedures, resources and readiness for handling security incidents. | H12: Draft
... A18: A.8.32 | B18: Change management | C18: Annex A | D18: Execution / Governance | E18: Variance Prevention; Variance Correction | F18: Scaling-sensitive | G18: Ensures changes are assessed, approved, implemented, verified and traceable. | H18: Draft

Sheet Dependencies
A1: Dependency ID | B1: Source control | C1: Target control | D1: Dependency type | E1: Logic | F1: Dependency group ID | G1: Impact % | H1: Confidence | I1: Rationale | J1: Failure effect | K1: Interpretation type | L1: Assumptions | M1: Status
A2: DEP-001 | B2: 4.3 | C2: A.5.9 | D2: Governance | E2: Direct | G2: 75 | H2: High | I2: Without clear ISMS boundaries, the asset inventory cannot reliably determine which assets must be included. | J2: Assets outside an unclear scope may be omitted or inconsistently managed. | K2: Standard-supported | L2: The ISMS scope is used as an input to asset inventory boundaries. | M2: Draft
A3: DEP-002 | B3: 5.3 | C3: A.5.9 | D3: Governance | E3: Direct | G3: 75 | H3: High | I3: Without assigned authority and accountability, the asset inventory cannot be reliably owned and maintained. | J3: Records become incomplete, outdated or disputed. | K3: Standard-supported | L3: Clause-level responsibilities are translated into operational ownership. | M3: Draft
A4: DEP-003 | B4: A.5.2 | C4: A.5.9 | D4: Governance | E4: Direct | G4: 75 | H4: High | I4: Without operational security responsibilities, asset ownership and maintenance duties are not consistently performed. | J4: Assets lack accountable owners and review actions are missed. | K4: Professional interpretation | L4: Asset owners or equivalent accountable roles are defined. | M4: Draft
A5: DEP-004 | B5: 7.5 | C5: A.5.9 | D5: Evidence | E5: Direct | G5: 50 | H5: High | I5: Without controlled documented information, inventory records may not remain approved, current and traceable. | J5: The inventory may exist but cannot be trusted as an authoritative source. | K5: Standard-supported | L5: The inventory is treated as controlled documented information. | M5: Draft
A6: DEP-005 | B6: A.5.9 | C6: 6.1.2 | D6: Data | E6: Direct | G6: 75 | H6: High | I6: Without reliable asset data, risk assessment cannot consistently identify what is exposed, owned or critical. | J6: Risk identification and impact analysis omit or misclassify assets. | K6: Professional interpretation | L6: Asset-based risk assessment is part of the organisation's method. | M6: Draft
A7: DEP-006 | B7: 6.1.2 | C7: A.5.9 | D7: Risk | E7: Direct | G7: 50 | H7: Medium | I7: Without risk context, the inventory cannot reliably capture the criticality and detail needed for security decisions. | J7: The inventory becomes a flat list with weak prioritisation value. | K7: Professional interpretation | L7: Risk assessment outputs inform asset criticality and required attributes. | M7: Draft
A8: DEP-007 | B8: A.5.9 | C8: A.8.8 | D8: Data | E8: Direct | G8: 75 | H8: High | I8: Without a reliable asset inventory, vulnerability management cannot define complete assessment and remediation coverage. | J8: Unknown or unmanaged assets remain outside scanning and remediation. | K8: Professional interpretation | L8: No equivalent automated discovery source fully replaces the inventory. | M8: Draft
A9: DEP-008 | B9: A.8.8 | C9: A.5.9 | D9: Data | E9: OR | F9: GRP-OR-001 | G9: 25 | H9: Medium | I9: Vulnerability assessment activities may reveal assets that are missing from the inventory. | J9: Inventory gaps remain undiscovered for longer. | K9: Professional interpretation | L9: Scanning reaches networks or environments where unknown assets may exist. | M9: Draft
A10: DEP-009 | B10: A.5.9 | C10: A.8.9 | D10: Data | E10: Direct | G10: 75 | H10: High | I10: Without known assets and ownership, configuration baselines cannot be assigned and maintained consistently. | J10: Systems lack an authoritative baseline or accountable owner. | K10: Professional interpretation | L10: Configuration management is implemented per asset or system class. | M10: Draft
A11: DEP-010 | B11: A.8.9 | C11: A.5.9 | D11: Data | E11: Direct | G11: 25 | H11: Medium | I11: Configuration repositories and baseline records can provide updates and validation data for the asset inventory. | J11: Inventory attributes become less accurate and less technically useful. | K11: Professional interpretation | L11: Configuration records include asset identifiers and ownership-relevant data. | M11: Draft
A12: DEP-011 | B12: A.5.9 | C12: A.8.15 | D12: Data | E12: Direct | G12: 50 | H12: Medium | I12: Without asset and criticality information, logging coverage and retention priorities cannot be set consistently. | J12: Important systems may produce insufficient logs while low-value data consumes resources. | K12: Professional interpretation | L12: Logging requirements vary by asset type or criticality. | M12: Draft
A13: DEP-012 | B13: A.8.15 | C13: A.5.9 | D13: Data | E13: OR | F13: GRP-OR-001 | G13: 25 | H13: Low | I13: Log sources may reveal systems or services that are absent from the inventory. | J13: Inventory gaps are less likely to be detected through operational telemetry. | K13: Hypothesis | L13: Log aggregation includes source identifiers that can be reconciled with the inventory. | M13: Draft
A14: DEP-013 | B14: A.5.9 | C14: A.8.16 | D14: Data | E14: Direct | G14: 50 | H14: Medium | I14: Without reliable asset scope and criticality, monitoring cannot consistently prioritise coverage and alert handling. | J14: Monitoring leaves blind spots or applies equal attention to unequal assets. | K14: Professional interpretation | L14: Monitoring priorities are risk- or asset-based. | M14: Draft
A15: DEP-014 | B15: A.8.16 | C15: A.5.9 | D15: Data | E15: OR | F15: GRP-OR-001 | G15: 25 | H15: Medium | I15: Monitoring and discovery activities may identify systems or services missing from the inventory. | J15: Unknown assets remain unrecorded and outside formal ownership. | K15: Professional interpretation | L15: Monitoring includes discovery or source reconciliation. | M15: Draft
A16: DEP-015 | B16: A.5.9 | C16: A.8.32 | D16: Data | E16: Direct | G16: 50 | H16: Medium | I16: Without identified assets and owners, changes cannot be consistently scoped, approved and linked to affected services. | J16: Changes are approved without complete impact or ownership information. | K16: Professional interpretation | L16: Change records reference affected assets or services. | M16: Draft
A17: DEP-016 | B17: A.8.32 | C17: A.5.9 | D17: Operational | E17: Direct | G17: 50 | H17: High | I17: Without change-driven inventory updates, the asset inventory cannot remain current after deployments, replacements or removals. | J17: The inventory drifts from the real environment. | K17: Professional interpretation | L17: The change process includes an inventory update or reconciliation step. | M17: Draft
A18: DEP-017 | B18: A.5.7 | C18: A.8.8 | D18: Data | E18: Direct | G18: 50 | H18: High | I18: Without relevant threat information, vulnerability management cannot prioritise exposure using active exploitation and threat capability. | J18: Remediation order relies too heavily on technical severity alone. | K18: Professional interpretation | L18: Threat intelligence is relevant and actionable for vulnerability prioritisation. | M18: Draft
A19: DEP-018 | B19: A.5.7 | C19: A.8.16 | D19: Data | E19: Direct | G19: 50 | H19: High | I19: Without threat information, monitoring cannot adapt detection logic and priorities to changes in attacker behaviour. | J19: Monitoring remains static while threats change. | K19: Professional interpretation | L19: Threat intelligence is translated into monitoring requirements or use cases. | M19: Draft
A20: DEP-019 | B20: A.8.8 | C20: A.8.32 | D20: Operational | E20: AND | F20: GRP-AND-001 | G20: 75 | H20: High | I20: Vulnerability treatment depends on controlled changes to deploy, test and verify remediation. | J20: Identified vulnerabilities remain unresolved or are fixed through unsafe changes. | K20: Professional interpretation | L20: Remediation changes are subject to the change process. | M20: Draft
A21: DEP-020 | B21: A.8.32 | C21: A.8.8 | D21: Operational | E21: AND | F21: GRP-AND-001 | G21: 75 | H21: High | I21: Without a functioning change process, vulnerability remediation cannot be reliably implemented and verified. | J21: Patches or configuration fixes are delayed, fail, or introduce new weaknesses. | K21: Professional interpretation | L21: Emergency changes are also controlled and retrospectively reviewed. | M21: Draft
A22: DEP-021 | B22: A.8.9 | C22: A.8.8 | D22: Data | E22: AND | F22: GRP-AND-001 | G22: 50 | H22: High | I22: Without configuration and version baselines, vulnerability assessment cannot reliably determine exposure or correct treatment. | J22: False positives, missed exposures and incorrect remediation decisions increase. | K22: Professional interpretation | L22: Baselines include versions and security-relevant configuration attributes. | M22: Draft
A23: DEP-022 | B23: A.8.8 | C23: A.8.9 | D23: Operational | E23: AND | F23: GRP-AND-001 | G23: 25 | H23: Medium | I23: Vulnerability remediation changes expected configurations and should update approved baselines. | J23: Baselines become obsolete after security fixes. | K23: Professional interpretation | L23: Remediation may include configuration changes as well as software updates. | M23: Draft
A24: DEP-023 | B24: A.8.32 | C24: A.8.9 | D24: Operational | E24: Direct | G24: 75 | H24: High | I24: Without controlled and verified changes, configuration baselines cannot remain authoritative. | J24: Unauthorised or undocumented configuration drift accumulates. | K24: Professional interpretation | L24: Approved changes update configuration records or baselines. | M24: Draft
A25: DEP-024 | B25: A.8.9 | C25: A.8.32 | D25: Data | E25: Direct | G25: 50 | H25: High | I25: Without a known baseline, change assessment cannot reliably determine what will change or whether the result is acceptable. | J25: Impact analysis and post-change verification are weakened. | K25: Professional interpretation | L25: A baseline exists for the affected system or configuration class. | M25: Draft
A26: DEP-025 | B26: A.8.9 | C26: A.8.15 | D26: Operational | E26: Direct | G26: 50 | H26: Medium | I26: Without controlled logging configurations, required event sources and settings may be disabled or changed. | J26: Logging coverage silently degrades. | K26: Professional interpretation | L26: Logging settings are part of configuration management. | M26: Draft
A27: DEP-026 | B27: A.8.15 | C27: A.8.16 | D27: Data | E27: AND | F27: GRP-AND-002 | G27: 75 | H27: High | I27: Without sufficient activity records and telemetry, monitoring cannot reliably identify abnormal behaviour. | J27: Monitoring operates with blind spots or insufficient context. | K27: Professional interpretation | L27: Logging is a major but not necessarily the only telemetry source. | M27: Draft
A28: DEP-027 | B28: A.8.16 | C28: A.5.25 | D28: Operational | E28: AND | F28: GRP-AND-002 | G28: 75 | H28: High | I28: Without monitoring outputs, security events cannot be consistently identified and submitted for assessment. | J28: Potential incidents remain unnoticed or are assessed too late. | K28: Professional interpretation | L28: Monitoring is a primary source of events requiring assessment. | M28: Draft
A29: DEP-028 | B29: A.8.15 | C29: A.5.25 | D29: Evidence | E29: AND | F29: GRP-AND-002 | G29: 50 | H29: Medium | I29: Without reliable logs, event assessment lacks evidence needed to understand activity, sequence and affected assets. | J29: Events are misclassified or cannot be investigated with confidence. | K29: Professional interpretation | L29: Relevant logs are available, time-synchronised and protected. | M29: Draft
A30: DEP-029 | B30: A.5.24 | C30: A.5.25 | D30: Governance | E30: AND | F30: GRP-AND-002 | G30: 75 | H30: High | I30: Without defined incident criteria, roles and procedures, event assessment and escalation decisions are inconsistent. | J30: Similar events receive different classifications and escalation actions. | K30: Professional interpretation | L30: Incident preparation includes event classification and escalation criteria. | M30: Draft
A31: DEP-030 | B31: A.5.25 | C31: A.5.24 | D31: Evidence | E31: Direct | G31: 25 | H31: Medium | I31: Event assessment records provide feedback on whether incident criteria, roles and procedures are practical. | J31: Incident preparation is improved less effectively and recurring decision weaknesses persist. | K31: Professional interpretation | L31: Assessment outcomes and lessons are reviewed. | M31: Draft
A32: DEP-031 | B32: 8.1 | C32: A.8.8 | D32: Governance | E32: Direct | G32: 50 | H32: High | I32: Without operational planning and control, vulnerability treatment activities are not consistently scheduled, resourced and managed. | J32: Assessment occurs but treatment execution is inconsistent. | K32: Standard-supported | L32: The organisation treats vulnerability management as an operational process. | M32: Draft
A33: DEP-032 | B33: 8.1 | C33: A.8.32 | D33: Governance | E33: Direct | G33: 50 | H33: High | I33: Without operational planning, change activities and externally provided changes are not consistently controlled. | J33: Changes bypass defined criteria or lack necessary resources. | K33: Standard-supported | L33: Change management is included in operational control arrangements. | M33: Draft
A34: DEP-033 | B34: 9.1 | C34: A.5.9 | D34: Evidence | E34: Direct | G34: 50 | H34: High | I34: Without monitoring and evaluation, the organisation cannot verify inventory completeness, accuracy and review performance. | J34: The inventory may be maintained but its reliability is unknown. | K34: Professional interpretation | L34: Inventory quality indicators or reconciliation checks are defined. | M34: Draft
A35: DEP-034 | B35: 9.1 | C35: A.8.8 | D35: Evidence | E35: Direct | G35: 50 | H35: High | I35: Without measurement and evaluation, vulnerability management cannot demonstrate coverage, timeliness or treatment effectiveness. | J35: The process may operate without evidence that risk exposure is reducing. | K35: Professional interpretation | L35: Coverage and remediation performance are measured. | M35: Draft
A36: DEP-035 | B36: 9.1 | C36: A.8.16 | D36: Evidence | E36: Direct | G36: 50 | H36: High | I36: Without evaluation, monitoring cannot demonstrate that use cases, alerts and response pathways remain effective. | J36: Monitoring activity is mistaken for effective detection. | K36: Professional interpretation | L36: Detection performance and coverage are reviewed. | M36: Draft
A37: DEP-036 | B37: 9.1 | C37: A.8.32 | D37: Evidence | E37: Direct | G37: 50 | H37: High | I37: Without measurement and evaluation, change management cannot demonstrate success rates, exception quality or control effectiveness. | J37: Repeated failed or unauthorised changes remain systemic. | K37: Professional interpretation | L37: Change outcomes and failures are measured. | M37: Draft
A38: DEP-037 | B38: A.8.16 | C38: 9.1 | D38: Data | E38: Direct | G38: 50 | H38: Medium | I38: Monitoring activities provide operational control data used in ISMS measurement and evaluation. | J38: Evaluation has less timely evidence of technical control performance. | K38: Professional interpretation | L38: Monitoring metrics are included in ISMS evaluation. | M38: Draft
A39: DEP-038 | B39: A.8.8 | C39: 9.1 | D39: Data | E39: Direct | G39: 25 | H39: Medium | I39: Vulnerability data provides evidence of exposure, treatment performance and recurring weaknesses. | J39: ISMS evaluation has less evidence about technical risk and remediation performance. | K39: Professional interpretation | L39: Vulnerability metrics are included in ISMS reporting. | M39: Draft
A40: DEP-039 | B40: A.8.32 | C40: 9.1 | D40: Data | E40: Direct | G40: 25 | H40: Medium | I40: Change records and outcomes provide evidence about operational control stability and failure patterns. | J40: ISMS evaluation misses an important source of operational risk data. | K40: Professional interpretation | L40: Change metrics are included in ISMS reporting. | M40: Draft
...

Sheet Dependency Groups
A1: Group ID | B1: Group name | C1: Logic | D1: Member controls | E1: Target outcome | F1: Failure rule | G1: Notes | H1: Status
A2: GRP-AND-001 | B2: Vulnerability remediation lifecycle | C2: AND | D2: A.5.9; A.8.8; A.8.9; A.8.32 | E2: Reliable identification, prioritisation, implementation and verification of technical vulnerability treatment. | F2: Major degradation in any member weakens the end-to-end remediation lifecycle. | G2: Members perform different functions and are not interchangeable. | H2: Draft
A3: GRP-AND-002 | B3: Detection and event assessment capability | C3: AND | D3: A.8.15; A.8.16; A.5.25; A.5.24 | E3: Reliable visibility, monitoring, recognition, assessment and escalation of security events. | F3: A major weakness in visibility, monitoring, assessment criteria or preparation degrades the overall capability. | G3: The exact telemetry mix may vary, but the functional chain remains necessary. | H3: Draft
A4: GRP-OR-001 | B4: Discovery of assets missing from the inventory | C4: OR | D4: A.8.8; A.8.15; A.8.16 | E4: Independent operational activities may reveal assets or services absent from the formal inventory. | F4: One effective member may partially reveal inventory gaps, but coverage and confidence differ. | G4: This is an illustrative compensating relationship, not equivalence between controls. | H4: Draft

Sheet Evidence
A1: Evidence ID | B1: Control ID | C1: Evidence item | D1: Evidence type | E1: Proves design | F1: Proves operation | G1: Proves effectiveness | H1: Owner | I1: Review frequency | J1: Notes
A2: EVD-001 | B2: A.5.9 | C2: Asset management policy or inventory procedure | D2: Document | E2: Yes | F2: No | G2: No | H2: Information security or asset management owner | I2: Annual | J2: Shows defined expectations, not actual completeness.
A3: EVD-002 | B3: A.5.9 | C3: Approved asset inventory with owner, status and review data | D3: Record | E3: Yes | F3: Yes | G3: Partial | H3: Asset owners / inventory custodian | I3: Quarterly | J3: Shows operation but not necessarily completeness.
A4: EVD-003 | B4: A.5.9 | C4: Reconciliation between inventory and discovery, scan or monitoring sources | D4: Report | E4: No | F4: Yes | G4: Yes | H4: IT / Security | I4: Monthly or quarterly | J4: Strong evidence of completeness and drift detection.
A5: EVD-004 | B5: A.8.8 | C5: Vulnerability management procedure and prioritisation criteria | D5: Document | E5: Yes | F5: No | G5: No | H5: Security owner | I5: Annual | J5: Shows process design.
A6: EVD-005 | B6: A.8.8 | C6: Vulnerability scan coverage report linked to known assets | D6: Report | E6: Partial | F6: Yes | G6: Partial | H6: Security operations | I6: Monthly | J6: Coverage should be reconciled with A.5.9.
A7: EVD-006 | B7: A.8.8 | C7: Remediation performance against defined time limits and exceptions | D7: Report | E7: No | F7: Yes | G7: Yes | H7: System owners / Security | I7: Monthly | J7: Shows whether identified exposure is treated.
A8: EVD-007 | B8: A.8.9 | C8: Approved secure configuration baselines | D8: Document | E8: Yes | F8: Partial | G8: No | H8: Platform or system owner | I8: Annual and after major change | J8: Design evidence; deployment must be verified separately.
A9: EVD-008 | B9: A.8.9 | C9: Configuration compliance or drift report | D9: Report | E9: No | F9: Yes | G9: Yes | H9: IT operations / Security | I9: Monthly | J9: Shows variance from approved state.
A10: EVD-009 | B10: A.8.9 | C10: Approved exceptions with owner, rationale and expiry | D10: Record | E10: Yes | F10: Yes | G10: Partial | H10: Risk or system owner | I10: At approval and review date | J10: Prevents unmanaged permanent deviation.
A11: EVD-010 | B11: A.8.15 | C11: Logging standard defining sources, events, retention and protection | D11: Document | E11: Yes | F11: No | G11: No | H11: Security architecture / Operations | I11: Annual | J11: Shows logging design.
A12: EVD-011 | B12: A.8.15 | C12: Log source onboarding and coverage report | D12: Report | E12: Partial | F12: Yes | G12: Partial | H12: Security operations | I12: Monthly | J12: Should be compared with asset inventory and scope.
... A23: EVD-022 | B23: A.5.25 | C23: Sampled event assessments showing consistent classification and escalation | D23: Record | E23: No | F23: Yes | G23: Yes | H23: Security operations / Incident response | I23: Quarterly | J23: Shows operational consistency.

Sheet Centrality
A1: Control ID | B1: Control name | C1: Direct downstream | D1: Direct upstream | E1: Weighted outgoing impact | F1: High-confidence downstream | G1: MVP foundation score | I1: This is a provisional direct-dependency score, not full graph centrality. Later versions should calculate downstream reach, weighted propagation, AND-group criticality and scenario coverage.
A2: 4.3 | B2: Determining the scope of the ISMS | C2: =COUNTIF(Dependencies!$B$2:$B$49,A2) -> 1 | D2: =COUNTIF(Dependencies!$C$2:$C$49,A2) -> 0 | E2: =SUMIF(Dependencies!$B$2:$B$49,A2,Dependencies!$G$2:$G$49) -> 75 | F2: =COUNTIFS(Dependencies!$B$2:$B$49,A2,Dependencies!$H$2:$H$49,"High") -> 1 | G2: =ROUND(35*(C2/MAX($C$2:$C$18))+50*(E2/MAX($E$2:$E$18))+15*(F2/MAX($F$2:$F$18)),0) -> 19
A3: 5.3 | B3: Organisational roles, responsibilities and authorities | C3: =COUNTIF(Dependencies!$B$2:$B$49,A3) -> 1 | D3: =COUNTIF(Dependencies!$C$2:$C$49,A3) -> 0 | E3: =SUMIF(Dependencies!$B$2:$B$49,A3,Dependencies!$G$2:$G$49) -> 75 | F3: =COUNTIFS(Dependencies!$B$2:$B$49,A3,Dependencies!$H$2:$H$49,"High") -> 1 | G3: =ROUND(35*(C3/MAX($C$2:$C$18))+50*(E3/MAX($E$2:$E$18))+15*(F3/MAX($F$2:$F$18)),0) -> 19
A4: 6.1.2 | B4: Information security risk assessment | C4: =COUNTIF(Dependencies!$B$2:$B$49,A4) -> 1 | D4: =COUNTIF(Dependencies!$C$2:$C$49,A4) -> 1 | E4: =SUMIF(Dependencies!$B$2:$B$49,A4,Dependencies!$G$2:$G$49) -> 50 | F4: =COUNTIFS(Dependencies!$B$2:$B$49,A4,Dependencies!$H$2:$H$49,"High") -> 0 | G4: =ROUND(35*(C4/MAX($C$2:$C$18))+50*(E4/MAX($E$2:$E$18))+15*(F4/MAX($F$2:$F$18)),0) -> 13
A5: 7.5 | B5: Documented information | C5: =COUNTIF(Dependencies!$B$2:$B$49,A5) -> 3 | D5: =COUNTIF(Dependencies!$C$2:$C$49,A5) -> 0 | E5: =SUMIF(Dependencies!$B$2:$B$49,A5,Dependencies!$G$2:$G$49) -> 150 | F5: =COUNTIFS(Dependencies!$B$2:$B$49,A5,Dependencies!$H$2:$H$49,"High") -> 3 | G5: =ROUND(35*(C5/MAX($C$2:$C$18))+50*(E5/MAX($E$2:$E$18))+15*(F5/MAX($F$2:$F$18)),0) -> 47
A6: 8.1 | B6: Operational planning and control | C6: =COUNTIF(Dependencies!$B$2:$B$49,A6) -> 2 | D6: =COUNTIF(Dependencies!$C$2:$C$49,A6) -> 0 | E6: =SUMIF(Dependencies!$B$2:$B$49,A6,Dependencies!$G$2:$G$49) -> 100 | F6: =COUNTIFS(Dependencies!$B$2:$B$49,A6,Dependencies!$H$2:$H$49,"High") -> 2 | G6: =ROUND(35*(C6/MAX($C$2:$C$18))+50*(E6/MAX($E$2:$E$18))+15*(F6/MAX($F$2:$F$18)),0) -> 31
A7: 9.1 | B7: Monitoring, measurement, analysis and evaluation | C7: =COUNTIF(Dependencies!$B$2:$B$49,A7) -> 5 | D7: =COUNTIF(Dependencies!$C$2:$C$49,A7) -> 3 | E7: =SUMIF(Dependencies!$B$2:$B$49,A7,Dependencies!$G$2:$G$49) -> 275 | F7: =COUNTIFS(Dependencies!$B$2:$B$49,A7,Dependencies!$H$2:$H$49,"High") -> 5 | G7: =ROUND(35*(C7/MAX($C$2:$C$18))+50*(E7/MAX($E$2:$E$18))+15*(F7/MAX($F$2:$F$18)),0) -> 81
A8: 10.1 | B8: Continual improvement | C8: =COUNTIF(Dependencies!$B$2:$B$49,A8) -> 3 | D8: =COUNTIF(Dependencies!$C$2:$C$49,A8) -> 1 | E8: =SUMIF(Dependencies!$B$2:$B$49,A8,Dependencies!$G$2:$G$49) -> 75 | F8: =COUNTIFS(Dependencies!$B$2:$B$49,A8,Dependencies!$H$2:$H$49,"High") -> 0 | G8: =ROUND(35*(C8/MAX($C$2:$C$18))+50*(E8/MAX($E$2:$E$18))+15*(F8/MAX($F$2:$F$18)),0) -> 28
A9: A.5.2 | B9: Information security roles and responsibilities | C9: =COUNTIF(Dependencies!$B$2:$B$49,A9) -> 4 | D9: =COUNTIF(Dependencies!$C$2:$C$49,A9) -> 0 | E9: =SUMIF(Dependencies!$B$2:$B$49,A9,Dependencies!$G$2:$G$49) -> 250 | F9: =COUNTIFS(Dependencies!$B$2:$B$49,A9,Dependencies!$H$2:$H$49,"High") -> 4 | G9: =ROUND(35*(C9/MAX($C$2:$C$18))+50*(E9/MAX($E$2:$E$18))+15*(F9/MAX($F$2:$F$18)),0) -> 69
A10: A.5.7 | B10: Threat intelligence | C10: =COUNTIF(Dependencies!$B$2:$B$49,A10) -> 2 | D10: =COUNTIF(Dependencies!$C$2:$C$49,A10) -> 0 | E10: =SUMIF(Dependencies!$B$2:$B$49,A10,Dependencies!$G$2:$G$49) -> 100 | F10: =COUNTIFS(Dependencies!$B$2:$B$49,A10,Dependencies!$H$2:$H$49,"High") -> 2 | G10: =ROUND(35*(C10/MAX($C$2:$C$18))+50*(E10/MAX($E$2:$E$18))+15*(F10/MAX($F$2:$F$18)),0) -> 31
A11: A.5.9 | B11: Inventory of information and other associated assets | C11: =COUNTIF(Dependencies!$B$2:$B$49,A11) -> 6 | D11: =COUNTIF(Dependencies!$C$2:$C$49,A11) -> 12 | E11: =SUMIF(Dependencies!$B$2:$B$49,A11,Dependencies!$G$2:$G$49) -> 375 | F11: =COUNTIFS(Dependencies!$B$2:$B$49,A11,Dependencies!$H$2:$H$49,"High") -> 3 | G11: =ROUND(35*(C11/MAX($C$2:$C$18))+50*(E11/MAX($E$2:$E$18))+15*(F11/MAX($F$2:$F$18)),0) -> 94
A12: A.5.24 | B12: Information security incident management planning and preparation | C12: =COUNTIF(Dependencies!$B$2:$B$49,A12) -> 1 | D12: =COUNTIF(Dependencies!$C$2:$C$49,A12) -> 2 | E12: =SUMIF(Dependencies!$B$2:$B$49,A12,Dependencies!$G$2:$G$49) -> 75 | F12: =COUNTIFS(Dependencies!$B$2:$B$49,A12,Dependencies!$H$2:$H$49,"High") -> 1 | G12: =ROUND(35*(C12/MAX($C$2:$C$18))+50*(E12/MAX($E$2:$E$18))+15*(F12/MAX($F$2:$F$18)),0) -> 19
A13: A.5.25 | B13: Assessment and decision on information security events | C13: =COUNTIF(Dependencies!$B$2:$B$49,A13) -> 1 | D13: =COUNTIF(Dependencies!$C$2:$C$49,A13) -> 3 | E13: =SUMIF(Dependencies!$B$2:$B$49,A13,Dependencies!$G$2:$G$49) -> 25 | F13: =COUNTIFS(Dependencies!$B$2:$B$49,A13,Dependencies!$H$2:$H$49,"High") -> 0 | G13: =ROUND(35*(C13/MAX($C$2:$C$18))+50*(E13/MAX($E$2:$E$18))+15*(F13/MAX($F$2:$F$18)),0) -> 9
... A18: A.8.32 | B18: Change management | C18: =COUNTIF(Dependencies!$B$2:$B$49,A18) -> 4 | D18: =COUNTIF(Dependencies!$C$2:$C$49,A18) -> 6 | E18: =SUMIF(Dependencies!$B$2:$B$49,A18,Dependencies!$G$2:$G$49) -> 225 | F18: =COUNTIFS(Dependencies!$B$2:$B$49,A18,Dependencies!$H$2:$H$49,"High") -> 3 | G18: =ROUND(35*(C18/MAX($C$2:$C$18))+50*(E18/MAX($E$2:$E$18))+15*(F18/MAX($F$2:$F$18)),0) -> 62

Sheet Overview
A1: ISO 27001 Control Dependency Map — MVP Source of Truth
A3: Version 0.1 | General dependency theory | Clauses 4–10 + selected Annex A controls
A5: Current dataset | B5: Count | D5: Core model decisions
A6: Controls | B6: =COUNTA(Controls!A2:A18) -> 17 | D6: Node model | E6: One ISO clause or Annex A control per node
A7: Dependencies | B7: =COUNTA(Dependencies!A2:A49) -> 48 | D7: Dependency basis | E7: General control theory, not one risk scenario
A8: Dependency groups | B8: =COUNTA('Dependency Groups'!A2:A4) -> 3 | D8: Impact | E8: 0 / 25 / 50 / 75 / 100 anchor points
A9: Evidence items | B9: =COUNTA(Evidence!A2:A23) -> 22 | D9: Confidence | E9: High / Medium / Low
D10: Control state | E10: Degraded source control
D11: Relationships | E11: Directed, typed, bidirectional where justified
A12: Interpretation rules | D12: Logic | E12: Direct, AND and OR
A13: Impact meaning | B13: Expected degradation of the target control when the source control is degraded; not total cyber-risk reduction. | D13: Primary output | E13: Structured data; interactive graph generated later
A14: Foundation control | B14: A control whose degradation causes the widest and strongest downstream degradation.
A15: Evidence | B15: Separate proof of design, operation and effectiveness.
A16: Scale | B16: Use scale-sensitivity labels instead of declaring controls 'for large companies only'.
A17: Quality rule | B17: Every dependency requires a clear rationale, failure effect, assumptions and confidence.
A20: Next review questions
A21: 1 | B21: Are source and target directions correct for every edge?
A22: 2 | B22: Is the dependency general enough to apply beyond one product or architecture?
A23: 3 | B23: Is the impact score defensible using the anchor definitions?
A24: 4 | B24: Does the evidence prove design, operation or actual effectiveness?
A25: 5 | B25: Which dependencies should be standard-supported rather than professional interpretation?
A26: 6 | B26: Which visual interaction should be prioritised: node impact, filtering, evidence cards or degradation simulation?
